<sdf version='1.4'>
  <model name='Hand'>
      <link name='/hand_base'>
            <pose>0 0 0  0 -0 0</pose>
      <inertial>
        <pose>5.0019e-05 -0.0044561 0.037268 0 -0 0</pose>
        <mass>0.60858</mass>
        <inertia>
          <ixx>0.0006986</ixx>
          <ixy>2.7577e-07</ixy>
          <ixz>-7.8138e-07</ixz>
          <iyy>0.00050354</iyy>
          <iyz>-6.44e-05</iyz>
          <izz>0.00062253</izz>
        </inertia>
      </inertial>
      <collision name='/hand_base_collision'>
        <pose>0 0 0 0 -0 0</pose>
        <geometry>
          <mesh>
            <scale>1 1 1</scale>
            <uri>model://bh280_standalone/meshes/hand_base_collision.STL</uri>
          </mesh>
        </geometry>
      </collision>
      <visual name='/hand_base_visual'>
        <pose>0 0 0 0 -0 0</pose>
        <geometry>
          <mesh>
            <scale>1 1 1</scale>
            <uri>model://bh280_standalone/meshes/hand_base.STL</uri>
          </mesh>
        </geometry>
      </visual>
      <velocity_decay>
        <linear>0</linear>
        <angular>0</angular>
      </velocity_decay>
      <sensor name='hand_contact0' type='contact'>
        <contact>
          <collision>/hand_base_collision</collision>
        </contact>
      </sensor>
    </link>
    <link name='/finger0_0'>
            <pose>-0.025 0 0.0754 -9.24446e-30 -2.56739e-16 -1.5708</pose>
      <inertial>
        <pose>0.030616 -7.3219e-05 -0.011201 0 -0 0</pose>
        <mass>0.14109</mass>
        <inertia>
          <ixx>2.0672e-05</ixx>
          <ixy>2.6024e-07</ixy>
          <ixz>6.3481e-06</ixz>
          <iyy>7.4105e-05</iyy>
          <iyz>1.7118e-08</iyz>
          <izz>6.8207e-05</izz>
        </inertia>
      </inertial>
      <collision name='/finger0_0_collision'>
        <pose>0 0 0 0 -0 0</pose>
        <geometry>
          <mesh>
            <scale>1 1 1</scale>
            <uri>model://bh280_standalone/meshes/finger0_0_collision.STL</uri>
          </mesh>
        </geometry>
      </collision>
      <visual name='/finger0_0_visual'>
        <pose>0 0 0 0 -0 0</pose>
        <geometry>
          <mesh>
            <scale>1 1 1</scale>
            <uri>model://bh280_standalone/meshes/finger0_0.STL</uri>
          </mesh>
        </geometry>
      </visual>
      <velocity_decay>
        <linear>0</linear>
        <angular>0</angular>
      </velocity_decay>
      <sensor name='hand_contact1' type='contact'>
        <contact>
          <collision>/finger0_0_collision</collision>
        </contact>
      </sensor>
    </link>
    <joint name='/j00' type='revolute'>
      <child>/finger0_0</child>
      <parent>/hand_base</parent>
      <axis>
        <xyz>-1.02059e-29 -2.56739e-16 -1</xyz>
        <limit>
          <lower>-1e+16</lower>
          <upper>1e+16</upper>
        </limit>
        <dynamics/>
      </axis>
    </joint>
    <link name='/finger0_1'>
            <pose>-0.0242 -0.05 0.0754 1.5708 -1.66533e-16 -1.5708</pose>
      <inertial>
        <pose>0.02295 0.0010739 0.00041752 0 -0 0</pose>
        <mass>0.04166</mass>
        <inertia>
          <ixx>3.1199e-06</ixx>
          <ixy>4.5115e-07</ixy>
          <ixz>-2.9813e-07</ixz>
          <iyy>1.6948e-05</iyy>
          <iyz>-1.8635e-08</iyz>
          <izz>1.5809e-05</izz>
        </inertia>
      </inertial>
      <collision name='/finger0_1_collision'>
        <pose>0 0 0 0 -0 0</pose>
        <geometry>
          <mesh>
            <scale>1 1 1</scale>
            <uri>model://bh280_standalone/meshes/finger0_1_collision.STL</uri>
          </mesh>
        </geometry>
      </collision>
      <visual name='/finger0_1_visual'>
        <pose>0 0 0 0 -0 0</pose>
        <geometry>
          <mesh>
            <scale>1 1 1</scale>
            <uri>model://bh280_standalone/meshes/finger0_1.STL</uri>
          </mesh>
        </geometry>
      </visual>
      <velocity_decay>
        <linear>0</linear>
        <angular>0</angular>
      </velocity_decay>
      <sensor name='hand_contact2' type='contact'>
        <contact>
          <collision>/finger0_1_collision</collision>
        </contact>
      </sensor>
    </link>
    <joint name='/j01' type='revolute'>
      <child>/finger0_1</child>
      <parent>/finger0_0</parent>
      <axis>
        <xyz>-1 3.60822e-15 -3.66374e-15</xyz>
        <limit>
          <lower>-1e+16</lower>
          <upper>1e+16</upper>
        </limit>
        <dynamics/>
      </axis>
    </joint>
    <link name='/finger0_2'>
            <pose>-0.0244 -0.119936 0.0784 1.5708 -0.698132 -1.5708</pose>
      <inertial>
        <pose>0.0253323 0.00167106 0.000102872 0 -0 0</pose>
        <mass>0.193423</mass>
        <inertia>
          <ixx>1.3063</ixx>
          <ixy>0.244496</ixy>
          <ixz>-0.0476463</ixz>
          <iyy>6.45563</iyy>
          <iyz>-0.00299703</iyz>
          <izz>5.99395</izz>
        </inertia>
      </inertial>
      <collision name='/finger0_2_collision'>
        <pose>0 0 0 0 -0 0</pose>
        <geometry>
          <mesh>
            <scale>1 1 1</scale>
            <uri>model://bh280_standalone/meshes/finger0_2_collision.STL</uri>
          </mesh>
        </geometry>
      </collision>
      <visual name='/finger0_2_visual'>
        <pose>0 0 0 0 -0 0</pose>
        <geometry>
          <mesh>
            <scale>1 1 1</scale>
            <uri>model://bh280_standalone/meshes/finger0_2.STL</uri>
          </mesh>
        </geometry>
      </visual>
      <velocity_decay>
        <linear>0</linear>
        <angular>0</angular>
      </velocity_decay>
      <sensor name='hand_contact3' type='contact'>
        <contact>
          <collision>/finger0_2_collision</collision>
        </contact>
      </sensor>
    </link>
    <joint name='/j02' type='revolute'>
      <child>/finger0_2</child>
      <parent>/finger0_1</parent>
      <axis>
        <xyz>-1 6.2006e-14 -3.33067e-15</xyz>
        <limit>
          <lower>-1e+16</lower>
          <upper>1e+16</upper>
        </limit>
        <dynamics/>
      </axis>
    </joint>
    <link name='/finger1_0'>
     <pose>0.025 0 0.0754 0 -0.0058448 -1.5708</pose>
      <inertial>
        <pose>0.030616 -7.3219e-05 -0.011201 0 -0 0</pose>
        <mass>0.14109</mass>
        <inertia>
          <ixx>2.0672e-05</ixx>
          <ixy>2.6024e-07</ixy>
          <ixz>6.3481e-06</ixz>
          <iyy>7.4105e-05</iyy>
          <iyz>1.7118e-08</iyz>
          <izz>6.8207e-05</izz>
        </inertia>
      </inertial>
      <collision name='/finger1_0_collision'>
        <pose>0 0 0 0 -0 0</pose>
        <geometry>
          <mesh>
            <scale>1 1 1</scale>
            <uri>model://bh280_standalone/meshes/finger1_0_collision.STL</uri>
          </mesh>
        </geometry>
      </collision>
      <visual name='/finger1_0_visual'>
        <pose>0 0 0 0 -0 0</pose>
        <geometry>
          <mesh>
            <scale>1 1 1</scale>
            <uri>model://bh280_standalone/meshes/finger1_0.STL</uri>
          </mesh>
        </geometry>
      </visual>
      <velocity_decay>
        <linear>0</linear>
        <angular>0</angular>
      </velocity_decay>
      <sensor name='hand_contact4' type='contact'>
        <contact>
          <collision>/finger1_0_collision</collision>
        </contact>
      </sensor>
    </link>
    <joint name='/j10' type='revolute'>
      <child>/finger1_0</child>
      <parent>/hand_base</parent>
      <axis>
        <xyz>-1.84907e-13 -5.03395e-08 0.999997</xyz>
        <limit>
          <lower>-1e+16</lower>
          <upper>1e+16</upper>
        </limit>
        <dynamics kp="0.7"/>
      </axis>
    </joint>
    <link name='/finger1_1'>
            <pose>0.0257998 -0.05 0.0754 1.5708 -0.0058448 -1.5708</pose>
      <inertial>
        <pose>0.02295 0.0010739 0.00041752 0 -0 0</pose>
        <mass>0.04166</mass>
        <inertia>
          <ixx>3.1199e-06</ixx>
          <ixy>4.5115e-07</ixy>
          <ixz>-2.9813e-07</ixz>
          <iyy>1.6948e-05</iyy>
          <iyz>-1.8635e-08</iyz>
          <izz>1.5809e-05</izz>
        </inertia>
      </inertial>
      <collision name='/finger1_1_collision'>
        <pose>0 0 0 0 -0 0</pose>
        <geometry>
          <mesh>
            <scale>1 1 1</scale>
            <uri>model://bh280_standalone/meshes/finger1_1_collision.STL</uri>
          </mesh>
        </geometry>
      </collision>
      <visual name='/finger1_1_visual'>
        <pose>0 0 0 0 -0 0</pose>
        <geometry>
          <mesh>
            <scale>1 1 1</scale>
            <uri>model://bh280_standalone/meshes/finger1_1.STL</uri>
          </mesh>
        </geometry>
      </visual>
      <velocity_decay>
        <linear>0</linear>
        <angular>0</angular>
      </velocity_decay>
      <sensor name='hand_contact5' type='contact'>
        <contact>
          <collision>/finger1_1_collision</collision>
        </contact>
      </sensor>
    </link>
    <joint name='/j11' type='revolute'>
      <child>/finger1_1</child>
      <parent>/finger1_0</parent>
      <axis>
        <xyz>-1 3.67321e-06 -3.46945e-15</xyz>
        <limit>
          <lower>-1e+16</lower>
          <upper>1e+16</upper>
        </limit>
        <dynamics/>
      </axis>
    </joint>
    <link name='/finger1_2'>
            <pose>0.0255996 -0.119917 0.0788087 1.5708 -0.705925 -1.5708</pose>
      <inertial>
        <pose>0.0253323 0.00167106 0.000102872 0 -0 0</pose>
        <mass>0.193423</mass>
        <inertia>
          <ixx>1.3063</ixx>
          <ixy>0.244496</ixy>
          <ixz>-0.0476463</ixz>
          <iyy>6.45563</iyy>
          <iyz>-0.00299704</iyz>
          <izz>5.99395</izz>
        </inertia>
      </inertial>
      <collision name='/finger1_2_collision'>
        <pose>0 0 0 0 -0 0</pose>
        <geometry>
          <mesh>
            <scale>1 1 1</scale>
            <uri>model://bh280_standalone/meshes/finger1_2_collision.STL</uri>
          </mesh>
        </geometry>
      </collision>
      <visual name='/finger1_2_visual'>
        <pose>0 0 0 0 -0 0</pose>
        <geometry>
          <mesh>
            <scale>1 1 1</scale>
            <uri>model://bh280_standalone/meshes/finger1_2.STL</uri>
          </mesh>
        </geometry>
      </visual>
      <velocity_decay>
        <linear>0</linear>
        <angular>0</angular>
      </velocity_decay>
      <sensor name='hand_contact6' type='contact'>
        <contact>
          <collision>/finger1_2_collision</collision>
        </contact>
      </sensor>
    </link>
    <joint name='/j12' type='revolute'>
      <child>/finger1_2</child>
      <parent>/finger1_1</parent>
      <axis>
        <xyz>-1 3.67321e-06 -3.48332e-15</xyz>
        <limit>
          <lower>-1e+16</lower>
          <upper>1e+16</upper>
        </limit>
        <dynamics/>
      </axis>
    </joint>
    <link name='/finger2_1'>
      <pose>-0.0008 0.05 0.0754 1.5708 -5.55112e-17 1.5708</pose>
      <inertial>
        <pose>0.02295 0.0010739 0.00041752 0 -0 0</pose>
        <mass>0.04166</mass>
        <inertia>
          <ixx>3.1199e-06</ixx>
          <ixy>4.5115e-07</ixy>
          <ixz>-2.9813e-07</ixz>
          <iyy>1.6948e-06</iyy>
          <iyz>-1.8635e-08</iyz>
          <izz>1.5809e-05</izz>
        </inertia>
      </inertial>
      <collision name='/finger2_1_collision'>
        <pose>0 0 0 0 -0 0</pose>
        <geometry>
          <mesh>
            <scale>1 1 1</scale>
            <uri>model://bh280_standalone/meshes/finger2_1_collision.STL</uri>
          </mesh>
        </geometry>
      </collision>
      <visual name='/finger2_1_visual'>
        <pose>0 0 0 0 -0 0</pose>
        <geometry>
          <mesh>
            <scale>1 1 1</scale>
            <uri>model://bh280_standalone/meshes/finger2_1.STL</uri>
          </mesh>
        </geometry>
      </visual>
      <velocity_decay>
        <linear>0</linear>
        <angular>0</angular>
      </velocity_decay>
      <sensor name='hand_contact7' type='contact'>
        <contact>
          <collision>/finger2_1_collision</collision>
        </contact>
      </sensor>
    </link>
    <joint name='/j21' type='revolute'>
      <child>/finger2_1</child>
      <parent>/hand_base</parent>
      <axis>
        <xyz>1 3.60822e-15 -3.60822e-15</xyz>
        <limit>
          <lower>-1e+16</lower>
          <upper>1e+16</upper>
        </limit>
        <dynamics/>
      </axis>
    </joint>
    <link name='/finger2_2'>
      <pose>-0.0006 0.119936 0.0784 1.5708 -0.698132 1.5708</pose>
      <inertial>
        <pose>0.0253323 0.00167106 0.000102872 0 -0 0</pose>
        <mass>0.193423</mass>
        <inertia>
          <ixx>1.3063</ixx>
          <ixy>0.244496</ixy>
          <ixz>-0.0476463</ixz>
          <iyy>6.45563</iyy>
          <iyz>-0.00299703</iyz>
          <izz>5.99395</izz>
        </inertia>
      </inertial>
      <collision name='/finger2_2_collision'>
        <pose>0 0 0 0 -0 0</pose>
        <geometry>
          <mesh>
            <scale>1 1 1</scale>
            <uri>model://bh280_standalone/meshes/finger2_2_collision.STL</uri>
          </mesh>
        </geometry>
      </collision>
      <visual name='/finger2_2_visual'>
        <pose>0 0 0 0 -0 0</pose>
        <geometry>
          <mesh>
            <scale>1 1 1</scale>
            <uri>model://bh280_standalone/meshes/finger2_2.STL</uri>
          </mesh>
        </geometry>
      </visual>
      <velocity_decay>
        <linear>0</linear>
        <angular>0</angular>
      </velocity_decay>
      <sensor name='hand_contact8' type='contact'>
        <contact>
          <collision>/finger2_2_collision</collision>
        </contact>
      </sensor>
    </link>
    <joint name='/j22' type='revolute'>
      <child>/finger2_2</child>
      <parent>/finger2_1</parent>
      <axis>
        <xyz>1 4.38538e-15 -3.60822e-15</xyz>
        <limit>
          <lower>-1e+16</lower>
          <upper>1e+16</upper>
        </limit>
        <dynamics/>
      </axis>
    </joint>
  </model>
</sdf>
